<?xml version="1.0"?>
<!--
*  Copyright (C) 2012, Laboratorio de Robotica Movel - ICMC/USP
 *  Rafael Luiz Klaser <rlklaser@gmail.com>
 *  http://lrm.icmc.usp.br
 *
 *  Apoio FAPESP: 2012/04555-4
 *
 *  This program is free software: you can redistribute it and/or modify
 *  it under the terms of the GNU General Public License as published by
 *  the Free Software Foundation, either version 3 of the License, or
 *  (at your option) any later version.
 *
 *  This program is distributed in the hope that it will be useful,
 *  but WITHOUT ANY WARRANTY; without even the implied warranty of
 *  MERCHANTABILITY or FITNESS FOR A PARTICULAR PURPOSE.  See the
 *  GNU General Public License for more details.
 *
 *  You should have received a copy of the GNU General Public License
 *  along with this program.  If not, see <http://www.gnu.org/licenses/>.
 */

/**
 * @file ackermann.urdf.xacro
 * @brief 
 * @author Rafael Luiz Klaser <rlklaser@gmail.com>
 * @date Dez 12, 2012
 *
 */
-->
<robot
	xmlns:xi="http://www.w3.org/2001/XInclude"
	xmlns:xacro="http://ros.org/wiki/xacro"
>
	<include filename="$(find lrm_description)/urdf/carina/wheels.urdf.xacro" />
	<include filename="$(find lrm_description)/urdf/carina/steer.ackermann.urdf.xacro" />
	<include filename="$(find lrm_description)/urdf/carina/front.ackermann.urdf.xacro" />

	<xacro:front_bar side="left" />
	<xacro:front_bar side="right" />

	<joint
		name="joint_rear_left_bar"
		type="fixed"
	>
		<parent link="rear_suspension_rot_link" />
		<child link="rear_left_bar_link" />
		<origin
			xyz="0 ${rear_axle/2} 0"
			rpy="0 0 0" />
	</joint>

	<joint
		name="joint_rear_right_bar"
		type="fixed"
	>
		<parent link="rear_suspension_rot_link" />
		<child link="rear_right_bar_link" />
		<origin
			xyz="0 ${-rear_axle/2} 0"
			rpy="0 0 0" />
	</joint>

	<joint
		name="ackermann_joint"
		type="revolute"
	>
		<limit
			lower="-0.5"
			upper="0.5"
			effort="100"
			velocity="10" />
		<axis xyz="0 0 1" />
		<parent link="steer_link" />
		<child link="ackermann_bar_link" />
		<origin
			xyz="-0.2 0 0"
			rpy="0 0 0" />
	</joint>
	
	<link name="ackermann_bar_link">
		<inertial>
			<mass value="1.0" />
			<origin xyz="0 0 0" />
			<inertia
				ixx="1.0"
				ixy="0.0"
				ixz="0.0"
				iyy="1.0"
				iyz="0.0"
				izz="1.0" />
		</inertial>
	</link>
</robot>