<?xml version="1.0"?>
<!--
*  Copyright (C) 2012, Laboratorio de Robotica Movel - ICMC/USP
 *  Rafael Luiz Klaser <rlklaser@gmail.com>
 *  http://lrm.icmc.usp.br
 *
 *  Apoio FAPESP: 2012/04555-4
 *
 *  This program is free software: you can redistribute it and/or modify
 *  it under the terms of the GNU General Public License as published by
 *  the Free Software Foundation, either version 3 of the License, or
 *  (at your option) any later version.
 *
 *  This program is distributed in the hope that it will be useful,
 *  but WITHOUT ANY WARRANTY; without even the implied warranty of
 *  MERCHANTABILITY or FITNESS FOR A PARTICULAR PURPOSE.  See the
 *  GNU General Public License for more details.
 *
 *  You should have received a copy of the GNU General Public License
 *  along with this program.  If not, see <http://www.gnu.org/licenses/>.
 */

/**
 * @file steeringwheel.urdf.xacro
 * @brief 
 * @author Rafael Luiz Klaser <rlklaser@gmail.com>
 * @date Dez 17, 2012
 *
 */
-->
<robot
	xmlns:xi="http://www.w3.org/2001/XInclude"
	xmlns:xacro="http://ros.org/wiki/xacro"
>
	<include filename="$(find lrm_description)/urdf/inertia_tensors.urdf.xacro" />
	<include filename="$(find lrm_description)/urdf/clubcar/templates.urdf.xacro" />

	<link name="base_steering_wheel">
		<xacro:inertial_minimal />
	</link>

	<link name="steering_wheel_link">
		<xacro:inertial_minimal />
		<visual>
			<origin
				xyz="0 0 0"
				rpy="0 ${-M_PI/2} 0" />
			<geometry>
				<mesh
					filename="package://lrm_description/meshes/steering_wheel.dae"
					scale="0.00045 0.00045 0.00045" />
			</geometry>
			<material name="Steer">
				<color rgba="1.0 1.0 0.0 1.0" />
			</material>
		</visual>
	</link>

	<joint
		name="joint_steering_wheel_bar"
		type="fixed"
	>
		<origin
			rpy="0 0 0"
			xyz="0.8 0.24 0.1" />
		<parent link="base_link" />
		<child link="base_steering_wheel" />
	</joint>

	<joint
		name="joint_steering_wheel"
		type="revolute"
	>
		<origin
			xyz="-0.15 0.0 0.0"
			rpy="${-M_PI/2} 0.6 0" />
		<axis
			xyz="1 0 0"
			rpy="0 0 0" />
		<limit
			effort="10.0"
			velocity="10.0"
			upper="${3*M_PI}"
			lower="${-3*M_PI}" />
		<parent link="base_steering_wheel" />
		<child link="steering_wheel_link" />
	</joint>	
</robot>