<?xml version="1.0" ?>

<robot
	name="CaRINA_I"
	xmlns:xi="http://www.w3.org/2001/XInclude"
	xmlns:gazebo="http://playerstage.sourceforge.net/gazebo/xmlschema/#gz"
	xmlns:model="http://playerstage.sourceforge.net/gazebo/xmlschema/#model"
	xmlns:sensor="http://playerstage.sourceforge.net/gazebo/xmlschema/#sensor"
	xmlns:body="http://playerstage.sourceforge.net/gazebo/xmlschema/#body"
	xmlns:geom="http://playerstage.sourceforge.net/gazebo/xmlschema/#geom"
	xmlns:joint="http://playerstage.sourceforge.net/gazebo/xmlschema/#joint"
	xmlns:interface="http://playerstage.sourceforge.net/gazebo/xmlschema/#interface"
	xmlns:rendering="http://playerstage.sourceforge.net/gazebo/xmlschema/#rendering"
	xmlns:renderable="http://playerstage.sourceforge.net/gazebo/xmlschema/#renderable"
	xmlns:controller="http://playerstage.sourceforge.net/gazebo/xmlschema/#controller"
	xmlns:physics="http://playerstage.sourceforge.net/gazebo/xmlschema/#physics"
>
	<!-- LINKs -->

	<link name="base_footprint">
		<!-- 
		<inertial>
			<mass value="0.0001" />
			<origin xyz="0 0 0" />
			<inertia
				ixx="0.0001"
				ixy="0.0"
				ixz="0.0"
				iyy="0.0001"
				iyz="0.0"
				izz="0.0001" />
		</inertial>
		<visual>
			<origin
				rpy="0 0 0"
				xyz="0 0 0" />
			<geometry>
				<box size="0.001 0.001 0.001" />
			</geometry>
			<material name="Green" />
		</visual>
		<collision>
			<origin
				rpy="0 0 0"
				xyz="0 0 0.0" />
			<geometry>
				<box size="0.001 0.001 0.001" />
			</geometry>
		</collision>
		 -->
	</link>

	<link name="box_link">
		<inertial>
			<mass value="10" />
			<origin xyz="0 0 0" />
			<inertia
				ixx="0.1"
				ixy="0"
				ixz="0"
				iyy="0.1"
				iyz="0"
				izz="0.1" />
		</inertial>
		<visual>
			<origin
				rpy="0 0 0"
				xyz="0 0 0" />
			<geometry>
				<box size="0.4 1.2 0.35" />
			</geometry>
			<material name="Box">
				<color rgba="0.0 0.4 0.0 0.95" />
			</material>
		</visual>
		<collision>
			<origin
				rpy="0 0 0"
				xyz="0 0 0" />
			<geometry>
				<box size="0.4 1.2 0.35" />
			</geometry>
		</collision>
	</link>

	<link name="base_odometry">
		<inertial>
			<mass value="0.0001" />
			<origin xyz="0 0 0" />
			<inertia
				ixx="0.0001"
				ixy="0.0"
				ixz="0.0"
				iyy="0.0001"
				iyz="0.0"
				izz="0.0001" />
		</inertial>
		<!-- 
		<visual>
			<origin
				rpy="0 0 0"
				xyz="0 0 0" />
			<geometry>
				<box size="0.001 0.001 0.001" />
			</geometry>
			<material name="Green" />
		</visual>
		<collision>
			<origin
				rpy="0 0 0"
				xyz="0 0 0.0" />
			<geometry>
				<box size="0.001 0.001 0.001" />
			</geometry>
		</collision>
	 -->
	</link>

	<link name="base_link">
		<inertial>
			<mass value="0.001" />
			<origin xyz="0 0 0" />
			<inertia
				ixx="0.0001"
				ixy="0.0"
				ixz="0.0"
				iyy="0.0001"
				iyz="0.0"
				izz="0.0001" />
		</inertial>
		<!-- 
		<visual>
			<origin
				rpy="0 0 0"
				xyz="0 0 0" />
			<geometry>
				<box size="0.001 0.001 0.001" />
			</geometry>
			<material name="Green" />
		</visual>
		<collision>
			<origin
				rpy="0 0 0"
				xyz="0 0 0" />
			<geometry>
				<box size="0.001 0.001 0.001" />
			</geometry>
		</collision>
		 -->
	</link>

	<link name="base_wheel_dir_link">
		<inertial>
			<mass value="0.1" />
			<origin xyz="0 0 0.0" />
			<inertia
				ixx="0.1"
				ixy="0"
				ixz="0"
				iyy="0.1"
				iyz="0"
				izz="0.1" />
		</inertial>
	</link>
	<link name="wheel_dir_link">
		<inertial>
			<mass value="0.5" />
			<origin xyz="0 0 0" />
			<inertia
				ixx="0.0027"
				ixy="0.0"
				ixz="0.0"
				iyy="0.0039"
				iyz="0.0"
				izz="0.0027" />
		</inertial>
		<visual>
			<origin
				xyz="0 0 0"
				rpy="0 -1.57 0" />
			<geometry>
				<mesh
					filename="package://carina_description/meshes/collada/golfcar/steering_wheel.dae"
					scale="0.00045 0.00045 0.00045" />
			</geometry>
			<material name="Steer">
				<color rgba="1.0 1.0 0.0 1.0" />
			</material>
		</visual>
		<collision>
			<origin
				xyz="0 0 0"
				rpy="0 0 0 " />
			<geometry>
				<cylinder
					radius="0.001"
					length="0.001" />
			</geometry>
		</collision>
	
	
	</link>

	<link name="chassis_1">
		<inertial>
			<mass value="300" />
			<origin xyz="0 0 0" />
			<inertia
				ixx="1.0"
				ixy="0.0"
				ixz="0.0"
				iyy="1.0"
				iyz="0.0"
				izz="1.0" />
		</inertial>
		<visual>
			<origin
				xyz="0 0 0.04"
				rpy="0 0 0" />
			<geometry>
				<mesh
					filename="package://carina_description/meshes/asiainsurance.mesh"
					scale="0.85 0.9 0.85" />
			</geometry>
			<material name="Car">
				<color rgba="0.0 1.0 0.0 1.0" />
			</material>
		</visual>

		<collision>
			<origin
				xyz="-0.12 0.0 0.0"
				rpy="0 0 0" />
			<geometry>
				<box size="2.8 1.2 1.5" />
				<!-- 
				<mesh
					filename="package://carina_description/meshes/collada/golfcar/carina.dae"
					scale="0.85 0.9 0.85" />
				 -->
			</geometry>
		</collision>
	</link>

	<link name="front_left_wheel">
		<inertial>
			<mass value="5.0" />
			<origin xyz="0 0 0" />
			<inertia
				ixx="0.0027"
				ixy="0.0"
				ixz="0.0"
				iyy="0.0039"
				iyz="0.0"
				izz="0.0027" />
		</inertial>
		<visual>
			<origin
				xyz="0 0 0"
				rpy="0 0 3.14159" />
			<geometry>
				<mesh
					filename="package://carina_description/meshes/collada/golfcar/roda.dae"
					scale="0.63 0.88 0.63" />
			</geometry>
			<material name="Roda">
				<color rgba="1.0 1.0 0.0 1.0" />
			</material>
		</visual>
		<collision>
			<origin
				xyz="0 0 0"
				rpy="1.57 0 0 " />
			<geometry>
				<cylinder
					radius="0.24"
					length="0.24" />
			</geometry>
		</collision>
	</link>

	<link name="front_right_wheel">
		<inertial>
			<mass value="5.0" />
			<origin xyz="0 0 0" />
			<inertia
				ixx="0.0027"
				ixy="0.0"
				ixz="0.0"
				iyy="0.0039"
				iyz="0.0"
				izz="0.0027" />
		</inertial>
		<visual>
			<origin
				xyz="0 0 0"
				rpy="0 0 0" />
			<geometry>
				<mesh
					filename="package://carina_description/meshes/collada/golfcar/roda.dae"
					scale="0.63 0.88 0.63" />
			</geometry>
			<material name="Roda">
				<color rgba="1.0 1.0 0.0 1.0" />
			</material>
		</visual>
		<collision>
			<origin
				xyz="0 0 0"
				rpy="1.57 0 0" />
			<geometry>
				<cylinder
					radius="0.24"
					length="0.24" />
			</geometry>
		</collision>
	</link>

	<link name="back_left_wheel">
		<inertial>
			<mass value="5.0" />
			<origin xyz="0 0 0" />
			<inertia
				ixx="0.0027"
				ixy="0.0"
				ixz="0.0"
				iyy="0.0039"
				iyz="0.0"
				izz="0.0027" />
		</inertial>
		<visual>
			<origin
				xyz="0 0 0"
				rpy="0 0 3.14159" />
			<geometry>
				<mesh
					filename="package://carina_description/meshes/collada/golfcar/roda.dae"
					scale="0.63 0.88 0.63" />
			</geometry>
			<material name="Roda">
				<color rgba="1.0 1.0 0.0 1.0" />
			</material>
		</visual>
		<collision>
			<origin
				xyz="0 0 0"
				rpy="1.57 0 0 " />
			<geometry>
				<cylinder
					radius="0.24"
					length="0.24" />
			</geometry>
		</collision>
	</link>

	<link name="back_right_wheel">
		<inertial>
			<mass value="5.0" />
			<origin xyz="0 0 0" />
			<inertia
				ixx="0.0027"
				ixy="0.0"
				ixz="0.0"
				iyy="0.0039"
				iyz="0.0"
				izz="0.0027" />
		</inertial>
		<visual>
			<origin
				xyz="0 0 0"
				rpy="0 0 0" />
			<geometry>
				<mesh
					filename="package://carina_description/meshes/collada/golfcar/roda.dae"
					scale="0.63 0.88 0.63" />
			</geometry>
			<material name="Roda">
				<color rgba="1.0 1.0 0.0 1.0" />
			</material>
		</visual>
		<collision>
			<origin
				xyz="0 0 0"
				rpy="1.57 0 0 " />
			<geometry>
				<cylinder
					radius="0.24"
					length="0.24" />
			</geometry>
		</collision>
	</link>

	<link name="back_left_wheel_dir">
		<inertial>
			<mass value="0.1" />
			<origin xyz="0 0 0" />
			<inertia
				ixx="0.01"
				ixy="0.0"
				ixz="0.0"
				iyy="0.01"
				iyz="0.0"
				izz="0.01" />
		</inertial>
		<visual>
			<origin
				xyz="0 0 0"
				rpy="0 0 0" />
			<geometry>
				<cylinder
					radius="0.03"
					length="0.045" />
			</geometry>
			<material name="Red">
				<color rgba="0.8 0.0 0.0 1.0" />
			</material>
		</visual>
		<collision>
			<origin
				xyz="0 0 0"
				rpy="0 0 0 " />
			<geometry>
				<cylinder
					radius="0.03"
					length="0.045" />
			</geometry>
		</collision>
	</link>

	<link name="back_right_wheel_dir">
		<inertial>
			<mass value="0.1" />
			<origin xyz="0 0 0" />
			<inertia
				ixx="0.01"
				ixy="0.0"
				ixz="0.0"
				iyy="0.01"
				iyz="0.0"
				izz="0.01" />
		</inertial>
		<visual>
			<cylinder
				radius="0.03"
				length="0.045" />
			<geometry>
				<cylinder
					radius="0.03"
					length="0.045" />
			</geometry>
			<material name="Red">
				<color rgba="0.8 0.0 0.0 1.0" />
			</material>
		</visual>
		<collision>
			<origin
				xyz="0 0 0"
				rpy="0 0 0 " />
			<geometry>
				<cylinder
					radius="0.03"
					length="0.045" />
			</geometry>
		</collision>
	</link>

	<link name="front_left_wheel_dir">
		<inertial>
			<mass value="0.1" />
			<origin xyz="0 0 0" />
			<inertia
				ixx="0.01"
				ixy="0.0"
				ixz="0.0"
				iyy="0.01"
				iyz="0.0"
				izz="0.01" />
		</inertial>
		<visual>
			<origin
				xyz="0 0 0"
				rpy="0 0 0" />
			<geometry>
				<cylinder
					radius="0.03"
					length="0.045" />
			</geometry>
			<material name="Red">
				<color rgba="0.8 0.0 0.0 1.0" />
			</material>
		</visual>
		<collision>
			<origin
				xyz="0 0 0"
				rpy="0 0 0 " />
			<geometry>
				<cylinder
					radius="0.03"
					length="0.045" />
			</geometry>
		</collision>
	</link>

	<link name="front_right_wheel_dir">
		<inertial>
			<mass value="0.1" />
			<origin xyz="0 0 0" />
			<inertia
				ixx="0.01"
				ixy="0.0"
				ixz="0.0"
				iyy="0.01"
				iyz="0.0"
				izz="0.01" />
		</inertial>
		<visual>
			<origin
				xyz="0 0 0"
				rpy="0 0 0" />
			<geometry>
				<cylinder
					radius="0.03"
					length="0.045" />
			</geometry>
			<material name="Red">
				<color rgba="0.8 0.0 0.0 1.0" />
			</material>
		</visual>
		<collision>
			<origin
				xyz="0 0 0"
				rpy="0 0 0 " />
			<geometry>
				<cylinder
					radius="0.03"
					length="0.045" />
			</geometry>
		</collision>
	</link>

	<link name="sick_parallel_laser_link">
		<inertial>
			<mass value="0.001" />
			<origin
				xyz="0 0 0"
				rpy="0 0 0" />
			<inertia
				ixx="0.0001"
				ixy="0"
				ixz="0"
				iyy="0.000001"
				iyz="0"
				izz="0.0001" />
		</inertial>
		<visual>
			<origin
				rpy="0 0 0"
				xyz="0.0 0 0" />
			<geometry>
				<cylinder
					length="0.12"
					radius="0.055" />
			</geometry>
			<material name="Black">
				<color rgba="0.0 0.0 0.0 1.0" />
			</material>
		</visual>
		<collision>
			<origin
				rpy="0 0 0"
				xyz="0.0 0 0" />
			<geometry>
				<cylinder
					length="0.0"
					radius="0.0" />
			</geometry>
		</collision>
	</link>

	<link name="sick_parallel_laser_box01_link">
		<inertial>
			<mass value="0.1" />
			<origin xyz="0 0 0.0" />
			<inertia
				ixx="0.1"
				ixy="0"
				ixz="0"
				iyy="0.1"
				iyz="0"
				izz="0.1" />
		</inertial>
		<visual>
			<origin
				rpy="0 0 0"
				xyz="0 0 0" />
			<geometry>
				<box size="0.11 0.15 0.11" />
			</geometry>
			<material name="Blue">
				<color rgba="0.0 0.0 0.8 1.0" />
			</material>
		</visual>
		<collision>
			<origin
				rpy="0 0 0"
				xyz="0 0 0" />
			<geometry>
				<box size="0.11 0.15 0.11" />
			</geometry>
		</collision>
	</link>

	<link name="sick_parallel_laser_box02_link">
		<inertial>
			<mass value="0.1" />
			<origin xyz="0 0 0.0" />
			<inertia
				ixx="0.1"
				ixy="0"
				ixz="0"
				iyy="0.1"
				iyz="0"
				izz="0.1" />
		</inertial>
		<visual>
			<origin
				rpy="0 0 0"
				xyz="0.045 0 0.09" />
			<geometry>
				<box size="0.2 0.15 0.07" />
			</geometry>
			<material name="Blue">
				<color rgba="0.0 0.0 0.8 1.0" />
			</material>
		</visual>
		<collision>
			<origin
				rpy="0 0 0"
				xyz="0.045 0 0.09" />
			<geometry>
				<box size="0.2 0.15 0.07" />
			</geometry>
		</collision>
	</link>

	<link name="sick_parallel_laser_box03_link">
		<inertial>
			<mass value="0.1" />
			<origin xyz="0 0 0.0" />
			<inertia
				ixx="0.1"
				ixy="0"
				ixz="0"
				iyy="0.1"
				iyz="0"
				izz="0.1" />
		</inertial>
		<visual>
			<origin
				rpy="0 0 0"
				xyz="0.045 0 -0.055" />
			<geometry>
				<box size="0.2 0.15 0.02" />
			</geometry>
			<material name="Blue">
				<color rgba="0.0 0.0 0.8 1.0" />
			</material>
		</visual>
		<collision>
			<origin
				rpy="0 0 0"
				xyz="0.045 0 -0.055" />
			<geometry>
				<box size="0.2 0.15 0.02" />
			</geometry>
		</collision>
	</link>

	<link name="sick_inclined_laser_link">
		<inertial>
			<mass value="0.001" />
			<origin
				xyz="0 0 0"
				rpy="0 0 0" />
			<inertia
				ixx="0.0001"
				ixy="0"
				ixz="0"
				iyy="0.000001"
				iyz="0"
				izz="0.0001" />
		</inertial>
		<visual>
			<origin
				rpy="0 0 0"
				xyz="0.0 0 0" />
			<geometry>
				<cylinder
					length="0.12"
					radius="0.055" />
			</geometry>
			<material name="Black">
				<color rgba="0.0 0.0 0.0 1.0" />
			</material>
		</visual>
		<collision>
			<origin
				rpy="0 0 0"
				xyz="0.0 0 0" />
			<geometry>
				<cylinder
					length="0.0"
					radius="0.0" />
			</geometry>
		</collision>
	</link>

	<link name="sick_inclined_laser_box01_link">
		<inertial>
			<mass value="0.1" />
			<origin xyz="0 0 0.0" />
			<inertia
				ixx="0.1"
				ixy="0"
				ixz="0"
				iyy="0.1"
				iyz="0"
				izz="0.1" />
		</inertial>
		<visual>
			<origin
				rpy="0 0 0"
				xyz="0 0 0" />
			<geometry>
				<box size="0.11 0.15 0.11" />
			</geometry>
			<material name="Blue">
				<color rgba="0.0 0.0 0.8 1.0" />
			</material>
		</visual>
		<collision>
			<origin
				rpy="0 0 0"
				xyz="0 0 0" />
			<geometry>
				<box size="0.11 0.15 0.11" />
			</geometry>
		</collision>
	</link>

	<link name="sick_inclined_laser_box02_link">
		<inertial>
			<mass value="0.1" />
			<origin xyz="0 0 0.0" />
			<inertia
				ixx="0.1"
				ixy="0"
				ixz="0"
				iyy="0.1"
				iyz="0"
				izz="0.1" />
		</inertial>
		<visual>
			<origin
				rpy="0 0 0"
				xyz="0.045 0 0.09" />
			<geometry>
				<box size="0.2 0.15 0.07" />
			</geometry>
			<material name="Blue">
				<color rgba="0.0 0.0 0.8 1.0" />
			</material>
		</visual>

		<collision>
			<origin
				rpy="0 0 0"
				xyz="0.045 0 0.09" />
			<geometry>
				<box size="0.2 0.15 0.07" />
			</geometry>
		</collision>
	</link>

	<link name="sick_inclined_laser_box03_link">
		<inertial>
			<mass value="0.1" />
			<origin xyz="0 0 0.0" />
			<inertia
				ixx="0.1"
				ixy="0"
				ixz="0"
				iyy="0.1"
				iyz="0"
				izz="0.1" />
		</inertial>
		<visual>
			<origin
				rpy="0 0 0"
				xyz="0.045 0 -0.055" />
			<geometry>
				<box size="0.2 0.15 0.02" />
			</geometry>
			<material name="Blue">
				<color rgba="0.0 0.0 0.8 1.0" />
			</material>
		</visual>
		<collision>
			<origin
				rpy="0 0 0"
				xyz="0.045 0 -0.055" />
			<geometry>
				<box size="0.2 0.15 0.02" />
			</geometry>
		</collision>
	</link>

	<link name="hokuyo_laser_right_link">
		<inertial>
			<mass value="0.001" />
			<origin
				xyz="0 0 0"
				rpy="0 0 0" />
			<inertia
				ixx="0.0001"
				ixy="0"
				ixz="0"
				iyy="0.000001"
				iyz="0"
				izz="0.0001" />
		</inertial>
		<visual>
			<origin
				rpy="0 0 0"
				xyz="0 0 0" />
			<geometry>
				<cylinder
					length="0.06"
					radius="0.0229" />
			</geometry>
			<material name="Black">
				<color rgba="0.0 0.0 0.0 1.0" />
			</material>
		</visual>
		<collision>
			<origin
				rpy="0 0 0"
				xyz="0 0 0" />
			<geometry>
				<cylinder
					length="0.0"
					radius="0.0" />
			</geometry>
		</collision>
	</link>

	<link name="hokuyo_laser_right_box_link">
		<inertial>
			<mass value="0.1" />
			<origin xyz="0 0 0.0" />
			<inertia
				ixx="0.1"
				ixy="0"
				ixz="0"
				iyy="0.1"
				iyz="0"
				izz="0.1" />
		</inertial>
		<visual>
			<origin
				rpy="0 0 0"
				xyz="0 0 0" />
			<geometry>
				<box size="0.05 0.05 0.05" />
			</geometry>
			<material name="Blue">
				<color rgba="0.0 0.0 0.8 1.0" />
			</material>
		</visual>
		<collision>
			<origin
				rpy="0 0 0"
				xyz="0 0 0" />
			<geometry>
				<box size="0.05 0.05 0.05" />
			</geometry>
		</collision>
	</link>

	<link name="hokuyo_laser_left_link">
		<inertial>
			<mass value="0.001" />
			<origin
				xyz="0 0 0"
				rpy="0 0 0" />
			<inertia
				ixx="0.0001"
				ixy="0"
				ixz="0"
				iyy="0.000001"
				iyz="0"
				izz="0.0001" />
		</inertial>
		<visual>
			<origin
				rpy="0 0 0"
				xyz="0 0 0" />
			<geometry>
				<cylinder
					length="0.06"
					radius="0.0229" />
			</geometry>
			<material name="Black">
				<color rgba="0.0 0.0 0.0 1.0" />
			</material>
		</visual>
		<collision>
			<origin
				rpy="0 0 0"
				xyz="0 0 0" />
			<geometry>
				<cylinder
					length="0.0"
					radius="0.0" />
			</geometry>
		</collision>
	</link>

	<link name="hokuyo_laser_left_box_link">
		<inertial>
			<mass value="0.1" />
			<origin xyz="0 0 0.0" />
			<inertia
				ixx="0.1"
				ixy="0"
				ixz="0"
				iyy="0.1"
				iyz="0"
				izz="0.1" />
		</inertial>
		<visual>
			<origin
				rpy="0 0 0"
				xyz="0 0 0" />
			<geometry>
				<box size="0.05 0.05 0.05" />
			</geometry>
			<material name="Blue">
				<color rgba="0.0 0.0 0.8 1.0" />
			</material>
		</visual>
		<collision>
			<origin
				rpy="0 0 0"
				xyz="0 0 0" />
			<geometry>
				<box size="0.05 0.05 0.05" />
			</geometry>
		</collision>
	</link>

	<link name="camera_base_link">
		<inertial>
			<mass value="0.1" />
			<origin xyz="0 0 0.0" />
			<inertia
				ixx="0.1"
				ixy="0"
				ixz="0"
				iyy="0.1"
				iyz="0"
				izz="0.1" />
		</inertial>
		<visual>
			<origin
				rpy="0 0 0"
				xyz="0 0 0" />
			<geometry>
				<box size="0.10 0.24 0.07" />
			</geometry>
			<material name="Blue">
				<color rgba="0.0 0.0 0.8 1.0" />
			</material>
		</visual>
		<collision>
			<origin
				rpy="0 0 0"
				xyz="0 0 0" />
			<geometry>
				<box size="0.10 0.24 0.07" />
			</geometry>
		</collision>
	</link>

	<link name="camera_optical_link">

		<inertial>
			<mass value="0.01" />
			<origin
				xyz="0 0 0"
				rpy="0 0 0" />
			<inertia
				ixx="0.001"
				ixy="0.0"
				ixz="0.0"
				iyy="0.001"
				iyz="0.0"
				izz="0.001" />
		</inertial>
	</link>

	<link name="imu_link">
		<inertial>
			<mass value="0.05" />
			<origin
				rpy="0 0 0"
				xyz="0 0 0" />
			<inertia
				ixx="0.0001"
				ixy="0"
				ixz="0"
				iyy="0.000001"
				iyz="0"
				izz="0.0001" />
		</inertial>
		<visual>
			<origin
				rpy="0 0 0"
				xyz="0 0 0" />
			<geometry>
				<box size="0.045 0.03 0.015" />
			</geometry>
			<material name="Orange">
				<color rgba="1 0.5 0.0 1.0" />
			</material>
		</visual>
		<collision>
			<origin
				rpy="0 0 0"
				xyz="0 0 0" />
			<geometry>
				<box size="0.02 0.04 0.02" />
			</geometry>
		</collision>
	</link>

	<!-- JOINTs -->

	<joint
		name="joint_base_link_base_wd"
		type="fixed"
	>
		<origin
			rpy="0 0 0"
			xyz="0.8 0.24 0.1" />
		<parent link="base_link" />
		<child link="base_wheel_dir_link" />
	</joint>

	<joint
		name="joint_base_link_wd"
		type="continuous"
	>
		<origin
			xyz="-0.15 0.0 0.0"
			rpy="-1.57 0.6 0" />
		<axis
			xyz="1 0 0"
			rpy="0 0 0" />
		<limit
			effort="500"
			velocity="500" />
		<joint_properties
			damping="0.0"
			friction="0.0" />
		<parent link="base_wheel_dir_link" />
		<child link="wheel_dir_link" />
	</joint>
		
	<joint
		name="base_link_box_joint"
		type="fixed"
	>
		<origin
			rpy="0 0 0"
			xyz="-1.05 0 -0.08" />
		<parent link="base_link" />
		<child link="box_link" />
	</joint>

	<joint
		name="base_odometry_joint"
		type="fixed"
	>
	<!-- encoder roda direita -->
		<origin
			rpy="0 0 0"
			xyz="-0.67 0 -0.7" />
		<parent link="base_link" />
		<child link="base_odometry" />
	</joint>

	<joint
		name="base_footprint_joint"
		type="fixed"
	>
		<origin
			rpy="0 0 0"
			xyz="0 0 0.745" />
		<parent link="base_footprint" />
		<child link="base_link" />
	</joint>

	<joint
		name="chassis_1_joint"
		type="fixed"
	>
		<origin
			xyz="0.15 0 0.28"
			rpy="0 0 0" />
		<parent link="base_link" />
		<child link="chassis_1" />
	</joint>

	<joint
		name="sick_parallel_laser_joint"
		type="fixed"
	>
		<axis xyz="0 1 0" />
		<origin
			rpy="0 0 0"
			xyz="1.34 0 -0.24" />
		<parent link="base_link" />
		<child link="sick_parallel_laser_link" />
	</joint>

	<joint
		name="sick_parallel_laser_box_joint"
		type="fixed"
	>
		<origin
			rpy="0 0 0"
			xyz="-0.08 0 0" />
		<parent link="sick_parallel_laser_link" />
		<child link="sick_parallel_laser_box01_link" />
	</joint>

	<joint
		name="spl_box01_box02_joint"
		type="fixed"
	>
		<origin
			rpy="0 0 0"
			xyz="0 0 0" />
		<parent link="sick_parallel_laser_box01_link" />
		<child link="sick_parallel_laser_box02_link" />
	</joint>

	<joint
		name="spl_box01_box03_joint"
		type="fixed"
	>
		<origin
			rpy="0 0 0"
			xyz="0 0 0" />
		<parent link="sick_parallel_laser_box01_link" />
		<child link="sick_parallel_laser_box03_link" />
	</joint>

	<joint
		name="sick_inclined_laser_joint"
		type="fixed"
	>
		<axis xyz="0 1 0" />
		<origin
			rpy="0 0.18 0"
			xyz="1.25 0 0.1" />
		<parent link="base_link" />
		<child link="sick_inclined_laser_link" />
	</joint>

	<joint
		name="sick_inclined_laser_box_joint"
		type="fixed"
	>
		<origin
			rpy="0 0 0"
			xyz="-0.08 0 0" />
		<parent link="sick_inclined_laser_link" />
		<child link="sick_inclined_laser_box01_link" />
	</joint>

	<joint
		name="sil_box01_box02_joint"
		type="fixed"
	>
		<origin
			rpy="0 0 0"
			xyz="0 0 0" />
		<parent link="sick_inclined_laser_box01_link" />
		<child link="sick_inclined_laser_box02_link" />
	</joint>

	<joint
		name="sil_box01_box03_joint"
		type="fixed"
	>
		<origin
			rpy="0 0 0"
			xyz="0 0 0" />
		<parent link="sick_inclined_laser_box01_link" />
		<child link="sick_inclined_laser_box03_link" />
	</joint>

	<joint
		name="hokuyo_laser_right_joint"
		type="fixed"
	>
		<axis xyz="0 1 0" />
		<origin
			rpy="3.14 0 -2.33"
			xyz="-1.25 -0.6 -0.3" />
		<parent link="base_link" />
		<child link="hokuyo_laser_right_link" />
	</joint>

	<joint
		name="hlr_box_joint"
		type="fixed"
	>
		<origin
			rpy="0 0 0"
			xyz="0 0 -0.03" />
		<parent link="hokuyo_laser_right_link" />
		<child link="hokuyo_laser_right_box_link" />
	</joint>

	<joint
		name="hokuyo_laser_left_joint"
		type="fixed"
	>
		<axis xyz="0 1 0" />
		<origin
			rpy="3.14 0 2.33"
			xyz="-1.25 0.6 -0.3" />
		<parent link="base_link" />
		<child link="hokuyo_laser_left_link" />
	</joint>

	<joint
		name="hll_box_joint"
		type="fixed"
	>
		<origin
			rpy="0 0 0"
			xyz="0 0 -0.03" />
		<parent link="hokuyo_laser_left_link" />
		<child link="hokuyo_laser_left_box_link" />
	</joint>

	<joint
		name="camera_base_mount_joint"
		type="fixed"
	>
		<origin
			rpy="0 0 0"
			xyz="1.2 0 0.49" />
		<parent link="base_link" />
		<child link="camera_base_link" />
	</joint>

	<joint
		name="camera_optical_frame_joint"
		type="fixed"
	>
		<origin
			xyz="0.0 0.0 0.1"
			rpy="0.0 0.0 0.0" />
		<parent link="camera_base_link" />
		<child link="camera_optical_link" />
	</joint>

	<joint
		name="imu_joint"
		type="fixed"
	>
		<axis xyz="1 0 0" /> <!-- 0 1 0 -->
		<origin xyz="-0.64 0 0.225" />
		<parent link="base_link" />
		<child link="imu_link" />
	</joint>

	<joint
		name="joint_front_left_wheel_dir"
		type="revolute"
	>
		<parent link="base_link" />
		<child link="front_left_wheel_dir" />
		<origin
			xyz="1.0 0.36 -0.5"
			rpy="0 0 0" />
		<axis
			xyz="0 0 1"
			rpy="0 0 0" />
		<limit
			effort="10.0"
			velocity="10.0"
			lower="-0.96" 
			upper="0.96" /> <!-- 55 grad -->
	</joint>

	<joint
		name="joint_front_right_wheel_dir"
		type="revolute"
	>
		<parent link="base_link" />
		<child link="front_right_wheel_dir" />
		<origin
			xyz="1.0 -0.36 -0.5"
			rpy="0 0 0" />
		<axis xyz="0 0 1" />
		<limit
			effort="10.0"
			velocity="10.0"
			lower="-0.96"
			upper="0.96" />
	</joint>

	<joint
		name="joint_back_left_wheel_dir"
		type="fixed"
	>
		<parent link="base_link" />
		<child link="back_left_wheel_dir" />
		<origin
			xyz="-0.64 0.41 -0.5"
			rpy="0 0 0" />
	</joint>

	<joint
		name="joint_back_right_wheel_dir"
		type="fixed"
	>
		<parent link="base_link" />
		<child link="back_right_wheel_dir" />
		<origin
			xyz="-0.64 -0.41 -0.5"
			rpy="0 0 0" />
	</joint>
	
	<joint
		name="joint_back_left_wheel"
		type="continuous"
	>
		<parent link="back_left_wheel_dir" />
		<child link="back_left_wheel" />
		<origin
			xyz="0.0 0.12 0"
			rpy="0 0 0" />
		<axis
			xyz="0 1 0"
			rpy="0 0 0" />
		<limit
			effort="100"
			velocity="100" />
		<joint_properties
			damping="0.0"
			friction="0.0" />
	</joint>

	<joint
		name="joint_back_right_wheel"
		type="continuous"
	>
		<parent link="back_right_wheel_dir" />
		<child link="back_right_wheel" />
		<origin
			xyz="0.0 -0.12 0"
			rpy="0 0 0" />
		<axis
			xyz="0 1 0"
			rpy="0 0 0" />
		<limit
			effort="100"
			velocity="100" />
		<joint_properties
			damping="0.0"
			friction="0.0" />
	</joint>

	<joint
		name="joint_front_left_wheel"
		type="continuous"
	>
		<parent link="front_left_wheel_dir" />
		<child link="front_left_wheel" />
		<origin
			xyz="0.0 0.12 0.0"
			rpy="0 0 0" />
		<axis xyz="0 1 0" />
		<limit
			effort="100"
			velocity="100" />
		<joint_properties
			damping="0.0"
			friction="0.0" />
	</joint>

	<joint
		name="joint_front_right_wheel"
		type="continuous"
	>
		<parent link="front_right_wheel_dir" />
		<child link="front_right_wheel" />
		<origin
			xyz="0.0 -0.12 0.0"
			rpy="0 0 0" />
		<axis xyz="0 1 0" />
		<limit
			effort="100"
			velocity="100" />
		<joint_properties
			damping="0.0"
			friction="0.0" />
	</joint>

	<!-- Transmissions -->
	<transmission
		name="joint_base_link_wd_trans"
		type="pr2_mechanism_model/SimpleTransmission"
	>
		<actuator name="joint_base_link_ww_motor" />
		<joint name="joint_base_link_wd" />
		<mechanicalReduction>1</mechanicalReduction>
		<motorTorqueConstant>1</motorTorqueConstant>
	</transmission>
	 
	<transmission
		name="joint_flw_trans"
		type="pr2_mechanism_model/SimpleTransmission"
	>
		<actuator name="joint_flw_motor" />
		<joint name="joint_front_left_wheel" />
		<mechanicalReduction>1</mechanicalReduction>
		<motorTorqueConstant>1</motorTorqueConstant>
	</transmission>
	
	<transmission
		name="joint_frw_trans"
		type="pr2_mechanism_model/SimpleTransmission"
	>
		<actuator name="joint_frw_motor" />
		<joint name="joint_front_right_wheel" />
		<mechanicalReduction>1</mechanicalReduction>
		<motorTorqueConstant>1</motorTorqueConstant>
	</transmission>
	
	<transmission
		name="joint_blw_trans"
		type="pr2_mechanism_model/SimpleTransmission"
	>
		<actuator name="joint_blw_motor" />
		<joint name="joint_back_left_wheel" />
		<mechanicalReduction>1</mechanicalReduction>
		<motorTorqueConstant>1</motorTorqueConstant>
	</transmission>

	<transmission
		name="joint_brw_trans"
		type="pr2_mechanism_model/SimpleTransmission"
	>
		<actuator name="joint_brw_motor" />
		<joint name="joint_back_right_wheel" />
		<mechanicalReduction>1</mechanicalReduction>
		<motorTorqueConstant>1</motorTorqueConstant>
	</transmission>

	<transmission
		name="joint_flw_trans_dir"
		type="pr2_mechanism_model/SimpleTransmission"
	>
		<actuator name="joint_flw_motor_dir" />
		<joint name="joint_front_left_wheel_dir" />
		<mechanicalReduction>1</mechanicalReduction>
		<motorTorqueConstant>1</motorTorqueConstant>
	</transmission>

	<transmission
		name="joint_frw_trans_dir"
		type="pr2_mechanism_model/SimpleTransmission"
	>
		<actuator name="joint_frw_motor_dir" />
		<joint name="joint_front_right_wheel_dir" />
		<mechanicalReduction>1</mechanicalReduction>
		<motorTorqueConstant>1</motorTorqueConstant>
	</transmission>
	
	<!-- GAZEBO -->
	<gazebo reference="chassis_1">
		<material>Gazebo/Green</material>
		<turnGravityOff>false</turnGravityOff>
	</gazebo>
	<gazebo reference="camera_base01_link">
		<material>Gazebo/Whith</material>
		<turnGravityOff>false</turnGravityOff>
	</gazebo>
	<gazebo reference="sick_inclined_laser_box01_link">
		<material>Gazebo/Blue</material>
		<turnGravityOff>false</turnGravityOff>
	</gazebo>
	<gazebo reference="sick_inclined_laser_box02_link">
		<material>Gazebo/Blue</material>
		<turnGravityOff>false</turnGravityOff>
	</gazebo>
	<gazebo reference="sick_parallel_laser_box03_link">
		<material>Gazebo/Blue</material>
		<turnGravityOff>false</turnGravityOff>
	</gazebo>
	<gazebo reference="sick_parallel_laser_box01_link">
		<material>Gazebo/Blue</material>
		<turnGravityOff>false</turnGravityOff>
	</gazebo>
	<gazebo reference="sick_parallel_laser_box02_link">
		<material>Gazebo/Blue</material>
		<turnGravityOff>false</turnGravityOff>
	</gazebo>
	<gazebo reference="sick_parallel_laser_box03_link">
		<material>Gazebo/Blue</material>
		<turnGravityOff>false</turnGravityOff>
	</gazebo>
	<gazebo reference="hokuyo_laser_right_box_link">
		<material>Gazebo/Black</material>
		<turnGravityOff>false</turnGravityOff>
	</gazebo>
	<gazebo reference="hokuyo_laser_left_box_link">
		<material>Gazebo/Black</material>
		<turnGravityOff>false</turnGravityOff>
	</gazebo>
	<gazebo reference="back_left_wheel_dir">
		<material>Gazebo/Red</material>
		<turnGravityOff>false</turnGravityOff>
	</gazebo>
	<gazebo reference="back_right_wheel_dir">
		<material>Gazebo/Red</material>
		<turnGravityOff>false</turnGravityOff>
	</gazebo>
	<gazebo reference="front_left_wheel_dir">
		<material>Gazebo/Red</material>
		<turnGravityOff>false</turnGravityOff>
	</gazebo>
	<gazebo reference="front_right_wheel_dir">
		<material>Gazebo/Red</material>
		<turnGravityOff>false</turnGravityOff>
	</gazebo>
	 
	 
	<!-- wheel -->
	<gazebo reference="front_left_wheel">
		<mu1 value="50.0" />
		<mu2 value="0.5" />
		<fdir1 value="1 0 0" />
		<material>Gazebo/Grey</material>
		<turnGravityOff>false</turnGravityOff>
	</gazebo>
	<gazebo reference="back_left_wheel">
		<mu1 value="50.0" />
		<mu2 value="0.5" />
		<fdir1 value="1 0 0" />
		<material>Gazebo/Grey</material>
		<turnGravityOff>false</turnGravityOff>
	</gazebo>
	<gazebo reference="back_right_wheel">
		<mu1 value="50.0" />
		<mu2 value="0.5" />
		<fdir1 value="1 0 0" />
		<material>Gazebo/Grey</material>
		<turnGravityOff>false</turnGravityOff>
	</gazebo>
	<gazebo reference="front_right_wheel">
		<mu1 value="50.0" />
		<mu2 value="0.5" />
		<fdir1 value="1 0 0" />
		<material>Gazebo/Grey</material>
		<turnGravityOff>false</turnGravityOff>
	</gazebo>

<!-- RoBombeiros -->
	<gazebo reference="sick_parallel_laser_link">
		<material>Gazebo/Black</material>
		<turnGravityOff>false</turnGravityOff>
		<sensor:gpu_ray name="sick_parallel_laser">
			<rayCount>21</rayCount>
			<rangeCount>21</rangeCount>
			<laserCount>1</laserCount>
			<origin>0.0 0.0 0.0</origin>
			<displayRays>lines</displayRays>
			<minAngle>-90.0</minAngle>
			<maxAngle>90.0</maxAngle>
			<minRange>0.05</minRange>
			<maxRange>30.1</maxRange>
			<resRange>0.001</resRange>
			<updateRate>10.0</updateRate>
			<controller:gazebo_ros_laser
				name="gazebo_ros_sick_laser_controller"
				plugin="libgazebo_ros_gpu_laser.so"
			>
				<hokuyoMinIntensity>101</hokuyoMinIntensity>
				<gaussianNoise>0.005</gaussianNoise>
				<alwaysOn>true</alwaysOn>
				<updateRate>10.0</updateRate>
				<topicName>base_scan</topicName>
				<frameName>laser_link</frameName>
				<interface:laser name="gazebo_ros_sick_laser_iface" />
			</controller:gazebo_ros_laser>
		</sensor:ray>
	</gazebo>
<!-- 
	<gazebo reference="sick_parallel_laser_link">
		<material>Gazebo/Black</material>
		<turnGravityOff>false</turnGravityOff>
		<sensor:ray name="sick_parallel_laser">
			<rayCount>640</rayCount>
			<rangeCount>640</rangeCount>
			<laserCount>1</laserCount>
			<origin>0.0 0.0 0.0</origin>
			<displayRays>fan</displayRays>
			<minAngle>-90.0</minAngle>
			<maxAngle>90.0</maxAngle>
			<minRange>0.05</minRange>
			<maxRange>80.1</maxRange>
			<resRange>0.001</resRange>
			<updateRate>10.0</updateRate>
			<controller:gazebo_ros_laser
				name="gazebo_ros_sick_laser_controller"
				plugin="libgazebo_ros_laser.so"
			>
				<hokuyoMinIntensity>101</hokuyoMinIntensity>
				<gaussianNoise>0.005</gaussianNoise>
				<alwaysOn>true</alwaysOn>
				<updateRate>10.0</updateRate>
				<topicName>scan_front</topicName>
				<frameName>sick_parallel_laser_link</frameName>
				<interface:laser name="gazebo_ros_sick_laser_iface" />
			</controller:gazebo_ros_laser>
		</sensor:ray>
	</gazebo>
-->
	<gazebo reference="sick_inclined_laser_link">
		<material>Gazebo/Black</material>
		<turnGravityOff>false</turnGravityOff>
		<sensor:ray name="sick_inclined_laser">
			<rayCount>640</rayCount>
			<rangeCount>640</rangeCount>
			<laserCount>1</laserCount>
			<origin>0.0 0.0 0.0</origin>
			<displayRays>fan</displayRays>
			<minAngle>-90.0</minAngle>
			<maxAngle>90.0</maxAngle>
			<minRange>0.05</minRange>
			<maxRange>0.01</maxRange>
			<resRange>0.001</resRange>
			<updateRate>10.0</updateRate>
			<controller:gazebo_ros_laser
				name="gazebo_ros_sick_inc_laser_controller"
				plugin="libgazebo_ros_laser.so"
			>
				<hokuyoMinIntensity>101</hokuyoMinIntensity>
				<gaussianNoise>0.005</gaussianNoise>
				<alwaysOn>true</alwaysOn>
				<updateRate>10.0</updateRate>
				<topicName>scan_inc</topicName>
				<frameName>sick_inclined_laser_link</frameName>
				<interface:laser name="gazebo_ros_sick_inc_laser_iface" />
			</controller:gazebo_ros_laser>
		</sensor:ray>
	</gazebo>

	<gazebo reference="hokuyo_laser_left_link">
		<material>Gazebo/Blue</material>
		<turnGravityOff>false</turnGravityOff>
		<sensor:ray name="hokuyo_laser_left">
			<rayCount>640</rayCount>
			<rangeCount>640</rangeCount>
			<laserCount>1</laserCount>
			<origin>0.0 0.0 0.0</origin>
			<displayRays>fan</displayRays>
			<minAngle>-130.0</minAngle>
			<maxAngle>130.0</maxAngle>
			<minRange>0.05</minRange>
			<maxRange>30.1</maxRange>
			<resRange>0.001</resRange>
			<updateRate>10.0</updateRate>
			<controller:gazebo_ros_laser
				name="gazebo_ros_hokuyo_laser_controller01"
				plugin="libgazebo_ros_laser.so"
			>
				<hokuyoMinIntensity>101</hokuyoMinIntensity>
				<gaussianNoise>0.005</gaussianNoise>
				<alwaysOn>true</alwaysOn>
				<updateRate>10.0</updateRate>
				<topicName>scan_rear1</topicName>
				<frameName>hokuyo_laser_left_link</frameName>
				<interface:laser name="gazebo_ros_hokuyo_laser_iface01" />
			</controller:gazebo_ros_laser>
		</sensor:ray>
	</gazebo>

	<gazebo reference="hokuyo_laser_right_link">
		<material>Gazebo/Blue</material>
		<turnGravityOff>false</turnGravityOff>
		<sensor:ray name="hokuyo_laser_right">
			<rayCount>640</rayCount>
			<rangeCount>640</rangeCount>
			<laserCount>1</laserCount>
			<origin>0.0 0.0 0.0</origin>
			<displayRays>fan</displayRays>
			<minAngle>-130.0</minAngle>
			<maxAngle>130.0</maxAngle>
			<minRange>0.05</minRange>
			<maxRange>30.1</maxRange>
			<resRange>0.001</resRange>
			<updateRate>10.0</updateRate>
			<controller:gazebo_ros_laser
				name="gazebo_ros_hokuyo_laser_controller02"
				plugin="libgazebo_ros_laser.so"
			>
				<hokuyoMinIntensity>101</hokuyoMinIntensity>
				<gaussianNoise>0.005</gaussianNoise>
				<alwaysOn>true</alwaysOn>
				<updateRate>10.0</updateRate>
				<topicName>scan_rear0</topicName>
				<frameName>hokuyo_laser_right_link</frameName>
				<interface:laser name="gazebo_ros_hokuyo_laser_iface02" />
			</controller:gazebo_ros_laser>
		</sensor:ray>
	</gazebo>

	<gazebo reference="camera_base_link">
		<material>Gazebo/Red</material>
		<turnGravityOff>false</turnGravityOff>
		<sensor:camera name="camera_sensor">
			<imageSize>640 480</imageSize>
			<imageFormat>R8G8B8</imageFormat>
			<hfov>90</hfov>
			<nearClip>0.1</nearClip>
			<farClip>100</farClip>
			<updateRate>15.0</updateRate>
			 
			<controller:gazebo_ros_camera
				name="camera_base_link_controller"
				plugin="libgazebo_ros_prosilica.so"
			>
			<!--
			<controller:gazebo_ros_camera name="camera_controller" plugin="libgazebo_ros_camera.so">
			-->
				<alwaysOn>true</alwaysOn>
				<updateRate>15.0</updateRate>
				<cameraName>camera</cameraName>
				<imageTopicName>image_raw</imageTopicName>
				<cameraInfoTopicName>camera_info</cameraInfoTopicName>
				<pollServiceName>request_image</pollServiceName>
				<frameName>camera_optical_link</frameName>
				<CxPrime>320</CxPrime>
				<Cx>320</Cx>
				<Cy>240</Cy>
				<focalLength>320</focalLength>
				<distortionK1>0</distortionK1>
				<distortionK2>0</distortionK2>
				<distortionK3>0</distortionK3>
				<distortionT1>0</distortionT1>
				<distortionT2>0</distortionT2>
			</controller:gazebo_ros_camera>
		</sensor:camera>
	</gazebo>
	
<!-- 
	<gazebo>
		<sensor name="cam" type="depth" always_on="1" update_rate="30" visualize="false">
			<origin pose="0.0232 0.06 0.098 0 -0 0" />
			<camera>
				<horizontal_fov angle="0.78539816339744828" />
				<image width="320" height="240" format="L8" />
				<clip near="0.10000000000000001" far="100" />
			</camera>
	    </sensor>
	</gazebo>
 -->
 	
	<gazebo>
<!-- 
		<controller:gazebo_ros_time
			name="gazebo_ros_time"
			plugin="libgazebo_ros_time.so"
		>
			<alwaysOn>true</alwaysOn>
			<updateRate>1000.0</updateRate>
			<interface:audio name="dummy_gazebo_ros_time_iface_should_not_be_here" />
		</controller:gazebo_ros_time>
 -->
		<controller:gazebo_ros_controller_manager
			name="gazebo_ros_controller_manager"
			plugin="libgazebo_ros_controller_manager.so"
		>
			<alwaysOn>true</alwaysOn>
			<updateRate>30</updateRate>
			<interface:audio name="gazebo_ros_controller_manager_dummy_iface" />
		</controller:gazebo_ros_controller_manager>	
		
		<controller:gazebo_ros_imu
			name="imu_controller"
			plugin="libgazebo_ros_imu.so"
		>
			<alwaysOn>true</alwaysOn>
			<updateRate>30</updateRate> <!-- 100 -->
			<bodyName>imu_link</bodyName>
			<topicName>imu_data</topicName>
			<serviceName>imu_service</serviceName>
			<gaussianNoise>2.89e-08</gaussianNoise>
			<interface:position name="imu_position" />
		</controller:gazebo_ros_imu>

		<controller:gazebo_ros_p3d
			name="p3d_base_controller"
			plugin="libgazebo_ros_p3d.so"
		>
			<alwaysOn>true</alwaysOn>
			<updateRate>30</updateRate>
			<bodyName>base_odometry</bodyName>
			<topicName>odom_gazebo</topicName>
			<gaussianNoise>0.01</gaussianNoise>
			<frameName>base_odometry</frameName>
			<interface:position name="p3d_base_position" />
		</controller:gazebo_ros_p3d>
	</gazebo>

</robot>

	