<?xml version="1.0"?>
<robot name="summit" 

       xmlns:xi="http://www.w3.org/2001/XInclude"
       xmlns:gazebo="http://playerstage.sourceforge.net/gazebo/xmlschema/#gz"
       xmlns:model="http://playerstage.sourceforge.net/gazebo/xmlschema/#model"
       xmlns:sensor="http://playerstage.sourceforge.net/gazebo/xmlschema/#sensor"
       xmlns:body="http://playerstage.sourceforge.net/gazebo/xmlschema/#body"
       xmlns:geom="http://playerstage.sourceforge.net/gazebo/xmlschema/#geom"
       xmlns:joint="http://playerstage.sourceforge.net/gazebo/xmlschema/#joint"
       xmlns:interface="http://playerstage.sourceforge.net/gazebo/xmlschema/#interface"
       xmlns:rendering="http://playerstage.sourceforge.net/gazebo/xmlschema/#rendering"
       xmlns:renderable="http://playerstage.sourceforge.net/gazebo/xmlschema/#renderable"
       xmlns:controller="http://playerstage.sourceforge.net/gazebo/xmlschema/#controller"
       xmlns:physics="http://playerstage.sourceforge.net/gazebo/xmlschema/#physics">


  <!-- BASE FOOTPRINT -->

  <!-- base_footprint is a fictitious link(frame) that is on the ground right below base_link origin,
             navigation stack depends on this frame -->
  <link name="base_footprint">
      <inertial>
          <mass value="0.0001" />
          <origin xyz="0 0 0" />
      <inertia ixx="0.0001" ixy="0.0" ixz="0.0"
                         iyy="0.0001" iyz="0.0" 
                         izz="0.0001" />
      </inertial>

      <visual>
          <origin xyz="0 0 0" rpy="0 0 0" />
          <geometry>
             <box size="0.001 0.001 0.001" />
          </geometry>
      </visual>

      <collision>
          <origin xyz="0 0 0.0" rpy="0 0 0" />
          <geometry>
            <box size="0.001 0.001 0.001" />
         </geometry>
     </collision>
  </link>

  <gazebo reference="base_footprint">
    <material>Gazebo/Green</material>
    <turnGravityOff>false</turnGravityOff>
  </gazebo>

  <joint name="base_footprint_joint" type="fixed">
     <!--NB: While you would think this would make it go up, it is oddly reversed.
      This moves the joint to 0,0,0 where we want it for rviz, etc. -->
     <!-- origin xyz="0 0 0.130" rpy="0 0 0" / -->
     <origin xyz="0 0 0.050" rpy="0 0 0"/>
     <parent link="base_footprint"/>
     <child link="base_link" />
  </joint>


  <!-- BASE_LINK (RED) -->

  <link name="base_link">
    <inertial>
      <mass value="6.5" />
      <origin xyz="0 0 0" />
      <inertia  ixx="0.21805" ixy="0.0"  ixz="-0.001"  iyy="0.33677"  iyz="0.0"  izz="0.20511" />
    </inertial>
    <visual>
       <origin xyz="0 0 0" rpy="0 0 0" />
       <geometry>
	 <mesh filename="package://summit_description/meshes/summit_chassis.stl"/>
       </geometry>
    </visual>
    <collision>
       <origin xyz="0 0 0.06" rpy="0 0 0 " />
       <geometry>
         <!--mesh filename="package://guardian_description/meshes/chassis.stl"/-->
	 <box size = "0.56 0.4 0.2"/>
       </geometry>
    </collision>     
  </link>
  <gazebo reference="base_link">
    <material>Gazebo/Red</material>
    <turnGravityOff>false</turnGravityOff>
  </gazebo>

<!-- DIRECTION BACK LEFT         -->
<!-- =========================== -->

  <link name="back_left_wheel_dir">
    <inertial>
      <mass value="0.1" />
      <!-- center of mass (com) is defined w.r.t. link local coord system -->
      <origin xyz="0 0 0" />
      <inertia  ixx="0.01" ixy="0.0"  ixz="0.0"  iyy="0.01"  iyz="0.0"  izz="0.01" />
    </inertial>
    <visual>
       <!-- visual origin is defined w.r.t. link local coordinate system -->
	<origin xyz="0 0 0" rpy="0 0 0" />       
	<!--origin xyz="0 0 0" rpy="0 0 1.5708" /-->
       <geometry>
         <cylinder radius="0.015" length="0.025"/>
         <!-- mesh filename="package://summit_description/meshes/wheel_axis.stl"/-->
       </geometry>
    </visual>
    <collision>
       <!-- collision origin is defined w.r.t. link local coord. system -->
       <origin xyz="0 0 0" rpy="0 0 0 " />
       <geometry>
         <cylinder radius="0.015" length="0.025"/>
       </geometry>
    </collision>
  </link>
  <gazebo reference="back_left_wheel_dir">
    <material>Gazebo/Green</material>
    <turnGravityOff>false</turnGravityOff>
  </gazebo>

  <joint name="joint_back_left_wheel_dir" type="revolute">
    <parent link="base_link"/>
    <child link="back_left_wheel_dir"/>
    <origin xyz="-0.185 0.105 0" rpy="0 0 0" />
    <axis xyz="0 0 1" rpy="0 0 0" />
    <limit effort="3.0" velocity="3.0" lower="-0.7854" upper="0.7854"/>
  </joint>

  <transmission name="joint_blw_trans_dir" type="pr2_mechanism_model/SimpleTransmission">
     <actuator name="joint_blw_motor_dir" />
     <joint name="joint_back_left_wheel_dir" />
     <mechanicalReduction>1</mechanicalReduction>
     <motorTorqueConstant>1</motorTorqueConstant>
  </transmission>


  <!-- BACK LEFT WHEEL -->
  <link name="back_left_wheel">
    <inertial>
      <mass value="1.023" />
      <origin xyz="0 0 0" /> 
      <inertia  ixx="0.0027" ixy="0.0"  ixz="0.0"  iyy="0.0039"  iyz="0.0"  izz="0.0027" />
    </inertial>
    <visual>
       <origin xyz="0 0 0" rpy="0 0 0 " /> 
       <geometry>
	 <!--mesh filename="package://guardian_description/meshes/wheel_link.dae" scale="1.8 1.8 1.8"/ -->
         <!--cylinder radius="0.085" length="0.08"/-->
	 <mesh filename="package://summit_description/meshes/wheel.stl"/>
       </geometry>
        <material name="grey">
             <color rgba="0.5 0.5 0.5 1"/>
        </material>
    </visual>
    <collision>
       <origin xyz="0 0 0" rpy="0 0 0 " />
       <geometry>
	 <!--mesh filename="package://guardian_description/meshes/wheel_link.dae" scale="1.8 1.8 1.8"/ -->
         <!--cylinder radius="0.085" length="0.08"/-->
         <mesh filename="package://summit_description/meshes/wheel.stl"/>
       </geometry>
    </collision>
  </link>
  <gazebo reference="back_left_wheel">
    <mu1 value="50.0"/> <!-- 2.0 -->
    <mu2 value="0.5"/> <!-- 0.5 -->
    <fdir1 value="1 0 0"/>
    <material>Gazebo/Grey</material>
    <turnGravityOff>false</turnGravityOff>
  </gazebo>

  <joint name="joint_back_left_wheel" type="continuous">
    <parent link="back_left_wheel_dir"/>
    <child link="back_left_wheel"/>
    <origin xyz="0.0 0.060 0" rpy="0 0 0" /> 
    <axis xyz="0 1 0" rpy="0 0 0" />
    <limit effort="100" velocity="100"/>
    <joint_properties damping="0.0" friction="0.0"/>
  </joint>

  <transmission name="joint_blw_trans" type="pr2_mechanism_model/SimpleTransmission">
     <actuator name="joint_blw_motor" />
     <joint name="joint_back_left_wheel" />
     <mechanicalReduction>1</mechanicalReduction>
     <motorTorqueConstant>1</motorTorqueConstant>
  </transmission>






<!-- DIRECTION BACK RIGHT        -->
<!-- =========================== -->
  <link name="back_right_wheel_dir">
    <inertial>
      <mass value="0.1" />
      <!-- center of mass (com) is defined w.r.t. link local coord system -->
      <origin xyz="0 0 0" />
      <inertia  ixx="0.01" ixy="0.0"  ixz="0.0"  iyy="0.01"  iyz="0.0"  izz="0.01" />
    </inertial>
    <visual>
       <!-- visual origin is defined w.r.t. link local coordinate system -->
       <origin xyz="0 0 0" rpy="0 0 0" />
       <geometry>
         <cylinder radius="0.015" length="0.025"/>
       </geometry>
    </visual>
    <collision>
       <!-- collision origin is defined w.r.t. link local coord. system -->
       <origin xyz="0 0 0" rpy="0 0 0 " />
       <geometry>
         <cylinder radius="0.015" length="0.025"/>
         <!--mesh filename="package://summit_description/meshes/wheel.stl"/-->
       </geometry>
    </collision>
  </link>
  <gazebo reference="back_right_wheel_dir">
    <material>Gazebo/Green</material>
    <turnGravityOff>false</turnGravityOff>
  </gazebo>

  <joint name="joint_back_right_wheel_dir" type="revolute">
    <parent link="base_link"/>
    <child link="back_right_wheel_dir"/>
    <origin xyz="-0.185 -0.105 0" rpy="0 0 0" />
    <axis xyz="0 0 1" rpy="0 0 0" />
    <limit effort="3.0" velocity="3.0" lower="-0.7854" upper="0.7854"/>
  </joint>

  <transmission name="joint_brw_trans_dir" type="pr2_mechanism_model/SimpleTransmission">
     <actuator name="joint_brw_motor_dir" />
     <joint name="joint_back_right_wheel_dir" />
     <mechanicalReduction>1</mechanicalReduction>
     <motorTorqueConstant>1</motorTorqueConstant>
  </transmission>

  <!-- BACK RIGHT WHEEL -->
  <link name="back_right_wheel">
    <inertial>
      <mass value="1.023" />
      <origin xyz="0 0 0" />
      <inertia  ixx="0.0027" ixy="0.0"  ixz="0.0"  iyy="0.0039"  iyz="0.0"  izz="0.0027" />
    </inertial>
    <visual>
       <origin xyz="0 0 0" rpy="0 0 0" /> 
       <geometry>
	 <!--mesh filename="package://guardian_description/meshes/wheel_link.dae" scale="1.8 1.8 1.8"/ -->
         <mesh filename="package://summit_description/meshes/wheel.stl"/>
       </geometry>
        <material name="grey">
                <color rgba="0.5 0.5 0.5 1"/>
        </material>
    </visual>
    <collision>
       <origin xyz="0 0 0" rpy="0 0 0" /> 
       <geometry>
	 <!-- mesh filename="package://guardian_description/meshes/wheel_link.dae" scale="1.8 1.8 1.8"/ -->
         <mesh filename="package://summit_description/meshes/wheel.stl"/>
       </geometry>
    </collision>
  </link>
  <gazebo reference="back_right_wheel">
    <mu1 value="50.0"/> <!-- 2.0 -->
    <mu2 value="0.5"/> <!-- 0.5 -->
    <fdir1 value="1 0 0"/>
    <material>Gazebo/Grey</material>
    <turnGravityOff>false</turnGravityOff>
  </gazebo>

  <joint name="joint_back_right_wheel" type="continuous">
    <parent link="back_right_wheel_dir"/>
    <child link="back_right_wheel"/>
    <origin xyz="0.0 -0.060 0" rpy="0 0 0" />
    <axis xyz="0 1 0" />
    <limit effort="100" velocity="100"/>
    <joint_properties damping="0.0" friction="0.0"/>
  </joint>

  <transmission name="joint_brw_trans" type="pr2_mechanism_model/SimpleTransmission">
     <actuator name="joint_brw_motor" />
     <joint name="joint_back_right_wheel" />
     <mechanicalReduction>1</mechanicalReduction>
     <motorTorqueConstant>1</motorTorqueConstant>
  </transmission>

<!-- DIRECTION FORWARD LEFT      -->
<!-- =========================== -->

  <link name="front_left_wheel_dir">
    <inertial>
      <mass value="0.1" />
      <!-- center of mass (com) is defined w.r.t. link local coord system -->
      <origin xyz="0 0 0" />
      <inertia  ixx="0.01" ixy="0.0"  ixz="0.0"  iyy="0.01"  iyz="0.0"  izz="0.01" />
    </inertial>
    <visual>
       <!-- visual origin is defined w.r.t. link local coordinate system -->
       <origin xyz="0 0 0" rpy="0 0 0" />
       <geometry>
         <cylinder radius="0.015" length="0.025"/>
       </geometry>
    </visual>
    <collision>
       <!-- collision origin is defined w.r.t. link local coord. system -->
       <origin xyz="0 0 0" rpy="0 0 0 " />
       <geometry>
         <cylinder radius="0.015" length="0.025"/>
       </geometry>
    </collision>
  </link>
  <gazebo reference="front_left_wheel_dir">
    <material>Gazebo/Green</material>
    <turnGravityOff>false</turnGravityOff>
  </gazebo>

  <joint name="joint_front_left_wheel_dir" type="revolute">
    <parent link="base_link"/>
    <child link="front_left_wheel_dir"/>
    <origin xyz="0.185 0.105 0" rpy="0 0 0" />
    <axis xyz="0 0 1" rpy="0 0 0" />
    <limit effort="3.0" velocity="3.0" lower="-0.7854" upper="0.7854"/>
  </joint>

  <transmission name="joint_flw_trans_dir" type="pr2_mechanism_model/SimpleTransmission">
     <actuator name="joint_flw_motor_dir" />
     <joint name="joint_front_left_wheel_dir" />
     <mechanicalReduction>1</mechanicalReduction>
     <motorTorqueConstant>1</motorTorqueConstant>
  </transmission>

  <!-- FRONT LEFT WHEEL (GREY) -->
  <link name="front_left_wheel">
    <inertial>
      <mass value="1.023" />
      <origin xyz="0 0 0" />
      <inertia  ixx="0.0027" ixy="0.0"  ixz="0.0"  iyy="0.0039"  iyz="0.0"  izz="0.0027" />
    </inertial>
    <visual>
       <origin xyz="0 0 0" rpy="0 0 0" /> 
       <geometry>
	 <!-- mesh filename="package://guardian_description/meshes/wheel_link.dae" scale="1.8 1.8 1.8"/ -->
         <mesh filename="package://summit_description/meshes/wheel.stl"/>
       </geometry>
	<material name="gray">
		<color rgba="0.5 0.5 0.5 1"/>
      	</material>
    </visual>
    <collision>
       <origin xyz="0 0 0" rpy="0 0 0" /> 
       <geometry>
	 <!-- mesh filename="package://guardian_description/meshes/wheel_link.dae" scale="1.8 1.8 1.8"/ -->
         <mesh filename="package://summit_description/meshes/wheel.stl"/>
       </geometry>
    </collision>
  </link>
  <gazebo reference="front_left_wheel">
    <mu1 value="50.0"/> <!-- 2.0 -->
    <mu2 value="0.5"/> <!-- 0.5 -->
    <fdir1 value="1 0 0"/>
    <material>Gazebo/Grey</material>
    <turnGravityOff>false</turnGravityOff>
  </gazebo>

  <joint name="joint_front_left_wheel" type="continuous">
    <parent link="front_left_wheel_dir"/>
    <child link="front_left_wheel"/>
    <origin xyz="0.0 0.0666666 0.0" rpy="0 0 0" />
    <axis xyz="0 1 0" />
    <limit effort="100" velocity="100"/>
    <joint_properties damping="0.0" friction="0.0"/>
  </joint>

  <transmission name="joint_flw_trans" type="pr2_mechanism_model/SimpleTransmission">
     <actuator name="joint_flw_motor" />
     <joint name="joint_front_left_wheel" />
     <mechanicalReduction>1</mechanicalReduction>
     <motorTorqueConstant>1</motorTorqueConstant>
  </transmission>


<!-- DIRECTION FORWARD RIGHT     -->
<!-- =========================== -->

  <link name="front_right_wheel_dir">
    <inertial>
      <mass value="0.1" />
      <!-- center of mass (com) is defined w.r.t. link local coord system -->
      <origin xyz="0 0 0" />
      <inertia  ixx="0.01" ixy="0.0"  ixz="0.0"  iyy="0.01"  iyz="0.0"  izz="0.01" />
    </inertial>
    <visual>
       <!-- visual origin is defined w.r.t. link local coordinate system -->
       <origin xyz="0 0 0" rpy="0 0 0" />
       <geometry>
         <cylinder radius="0.015" length="0.025"/>
       </geometry>
    </visual>
    <collision>
       <!-- collision origin is defined w.r.t. link local coord. system -->
       <origin xyz="0 0 0" rpy="0 0 0 " />
       <geometry>
         <cylinder radius="0.015" length="0.025"/>
       </geometry>
    </collision>
  </link>
  <gazebo reference="front_right_wheel_dir">
    <material>Gazebo/Green</material>
    <turnGravityOff>false</turnGravityOff>
  </gazebo>

  <joint name="joint_front_right_wheel_dir" type="revolute">
    <parent link="base_link"/>
    <child link="front_right_wheel_dir"/>
    <origin xyz="0.185 -0.105 0" rpy="0 0 0" />
    <axis xyz="0 0 1" rpy="0 0 0" />
    <limit effort="3.0" velocity="3.0" lower="-0.7854" upper="0.7854"/>
  </joint>

  <transmission name="joint_frw_trans_dir" type="pr2_mechanism_model/SimpleTransmission">
     <actuator name="joint_frw_motor_dir" />
     <joint name="joint_front_right_wheel_dir" />
     <mechanicalReduction>1</mechanicalReduction>
     <motorTorqueConstant>1</motorTorqueConstant>
  </transmission>


  <!-- FRONT RIGHT WHEEL (GREY) -->

  <link name="front_right_wheel">
    <inertial>
      <mass value="1.023" />
      <origin xyz="0 0 0" />
      <inertia  ixx="0.0027" ixy="0.0"  ixz="0.0"  iyy="0.0039"  iyz="0.0"  izz="0.0027" />
    </inertial>
    <visual>
       <origin xyz="0 0 0" rpy="0 0 0" /> 
       <geometry>
	 <!-- mesh filename="package://guardian_description/meshes/wheel_link.dae" scale="1.8 1.8 1.8"/ -->
         <mesh filename="package://summit_description/meshes/wheel.stl"/>
       </geometry>
	<material name="grey">
		<color rgba="0.5 0.5 0.5 1"/>
      	</material>
    </visual>
    <collision>
       <origin xyz="0 0 0" rpy="0 0 0" /> 
       <geometry>
	 <!-- mesh filename="package://guardian_description/meshes/wheel_link.dae" scale="1.8 1.8 1.8"/ -->
         <mesh filename="package://summit_description/meshes/wheel.stl"/>
       </geometry>
    </collision>
  </link>
  <gazebo reference="front_right_wheel">
    <mu1 value="50.0"/> <!-- 2.0 -->
    <mu2 value="0.5"/> <!-- 0.5 -->
    <fdir1 value="1 0 0"/>
    <material>Gazebo/Grey</material>
    <turnGravityOff>false</turnGravityOff>
  </gazebo>

  <joint name="joint_front_right_wheel" type="continuous">
    <parent link="front_right_wheel_dir"/>
    <child link="front_right_wheel"/>
    <origin xyz="0.0 -0.06 0" rpy="0 0 0" />
    <axis xyz="0 1 0" />
    <limit effort="100" velocity="100"/>
    <joint_properties damping="0.0" friction="0.0"/>
  </joint>

  <transmission name="joint_frw_trans" type="pr2_mechanism_model/SimpleTransmission">
     <actuator name="joint_frw_motor" />
     <joint name="joint_front_right_wheel" />
     <mechanicalReduction>1</mechanicalReduction>
     <motorTorqueConstant>1</motorTorqueConstant>
  </transmission>


  <!-- HOKUYO SENSOR -->

  <joint name="hokuyo_laser_joint" type="fixed">
     <axis xyz="0 1 0" />
     <origin xyz="0.226 0 0.226"/>  
     <!--origin xyz="0.226 0 0.126"/-->
     <parent link="base_link"/>
     <child link="hokuyo_laser_link"/>
  </joint>
 
 <link name="hokuyo_laser_link" type="laser">
     <inertial>
       <mass value="0.001" />
       <origin xyz="0 0 0" rpy="0 0 0" />
       <inertia ixx="0.0001" ixy="0" ixz="0" iyy="0.000001" iyz="0" izz="0.0001" />
    </inertial>
  </link>

  <!-- This adds a visual box to allow us to see the Hokuyo in rviz/gazebo -->
  <joint name="hokuyo_laser_box_joint" type="fixed">
    <origin xyz="0 0 0" rpy="0 0 0" />
    <parent link="hokuyo_laser_link" />
    <child link="hokuyo_laser_box_link"/>
  </joint>
  <link name="hokuyo_laser_box_link">
    <inertial>
      <mass value="0.01" />
      <origin xyz="0 0 0" />
      <inertia ixx="0.001"  ixy="0.0"  ixz="0.0"
               iyy="0.001"  iyz="0.0"
               izz="0.001" />
    </inertial>
    <visual>
      <origin xyz="0 0 0" rpy="0 0 0"/>
      <geometry>
        <!--box size="0.05 0.05 0.1" /-->
	<mesh filename= "package://pr2_description/meshes/tilting_laser_v0/hok_tilt.stl" scale="0.5 0.5 0.5"/>
      </geometry>
    </visual>
    <collision>
      <origin xyz="0 0 0" rpy="0 0 0"/>
      <geometry>
        <box size="0.05 0.05 0.1" />
      </geometry>
    </collision>
  </link>

  <gazebo reference="hokuyo_laser_box_link">
    <material>Gazebo/Magenta</material>
    <turnGravityOff>false</turnGravityOff>
  </gazebo>

  <!-- IMU SENSOR -->

  <joint name="imu_joint" type="fixed">
      <axis xyz="1 0 0"/> <!-- 0 1 0 -->
      <origin xyz="0 0 0.2825"/>
      <parent link="base_link"/>
      <child link="imu_link"/>
  </joint>


  <link name="imu_link">
      <inertial>
        <mass value="0.001"/>
        <origin rpy="0 0 0" xyz="0 0 0"/>
        <inertia ixx="0.0001" ixy="0" ixz="0" iyy="0.000001" iyz="0" izz="0.0001"/>
      </inertial>
      <visual>
        <origin rpy="0 0 0" xyz="0 0 0"/>
        <geometry>
          <box size="0.001 0.001 0.001"/>
        </geometry>
      </visual>
      <collision>
        <origin rpy="0 0 0" xyz="0 0 0"/>
        <geometry>
          <box size=".001 .001 .001"/>
        </geometry>
      </collision>
  </link>

  <!-- Gazebo controllers -->
  <gazebo>
     <controller:gazebo_ros_time name="gazebo_ros_time" plugin="libgazebo_ros_time.so">
       <alwaysOn>true</alwaysOn>
       <updateRate>1000.0</updateRate>
       <interface:audio name="dummy_gazebo_ros_time_iface_should_not_be_here"/>
     </controller:gazebo_ros_time>

      <!-- PR2_ACTARRAY -->
     <controller:gazebo_ros_controller_manager name="gazebo_ros_controller_manager" plugin="libgazebo_ros_controller_manager.so">
       <alwaysOn>true</alwaysOn>
       <updateRate>1000.0</updateRate>
       <interface:audio name="gazebo_ros_controller_manager_dummy_iface" />
     </controller:gazebo_ros_controller_manager>
  </gazebo>

  <!-- Other controllers (HOKUYO SENSOR) -->

  <gazebo reference = "hokuyo_laser_link">
    <sensor:ray name="hokuyo_laser">
       <rayCount>640</rayCount>
       <rangeCount>640</rangeCount>
       <laserCount>1</laserCount>

       <origin>0.0 0.0 0.0</origin>
       <displayRays>fan</displayRays>

       <minAngle>-120.0</minAngle>
       <maxAngle>120.0</maxAngle>
     
       <minRange>0.05</minRange>
       <maxRange>4.0</maxRange>
       <resRange>0.001</resRange>
       <updateRate>10.0</updateRate>
       <controller:gazebo_ros_laser name="gazebo_ros_hokuyo_laser_controller" plugin="libgazebo_ros_laser.so">
         <gaussianNoise>0.005</gaussianNoise>
         <alwaysOn>true</alwaysOn>
         <updateRate>10.0</updateRate>
         <!--topicName>hokuyo_laser_topic</topicName-->
         <topicName>base_scan</topicName>
         <frameName>hokuyo_laser_link</frameName>
         <interface:laser name="gazebo_ros_hokuyo_laser_iface" />
       </controller:gazebo_ros_laser>
    </sensor:ray>
   </gazebo>

   <!-- Other controllers (IMU SENSOR) -->

  <!--gazebo reference = "imu_link">
      <material>Gazebo/Green</material>
      <turnGravityOff>false</turnGravityOff>
      <controller:gazebo_ros_imu name="imu_controller" plugin="libgazebo_ros_imu.so">
         <alwaysOn>true</alwaysOn>
         <updateRate>50.0</updateRate>
         <bodyName>imu_link</bodyName>
         <topicName>imu_data</topicName>
         <xyzOffsets>0 0 0</xyzOffsets--> <!-- option to initialize odometry for fake localization-->
         <!--rpyOffsets>0 0 0</rpyOffsets>
	 <gaussianNoise>0.01</gaussianNoise>
	 <frameName>map</frameName>
         <interface:position name="imu_base_position"/--> <!--imu_position_iface-->
      <!--/controller:gazebo_ros_imu>
  </gazebo-->

  <gazebo>
      <material>Gazebo/Green</material>
      <turnGravityOff>false</turnGravityOff>
    <controller:gazebo_ros_imu name="imu_controller" plugin="libgazebo_ros_imu.so">
      <alwaysOn>true</alwaysOn>
      <updateRate>50.0</updateRate> <!-- 100 -->
      <bodyName>imu_link</bodyName>
      <topicName>imu_data</topicName>
      <gaussianNoise>2.89e-08</gaussianNoise>
      <xyzOffsets>0 0 0</xyzOffsets>
      <rpyOffsets>0 0 0</rpyOffsets>
      <interface:position name="imu_position"/>
    </controller:gazebo_ros_imu>
  </gazebo>

</robot>

