<?xml version="1.0"?>
<!--
*  Copyright (C) 2012, Laboratorio de Robotica Movel - ICMC/USP
 *  Rafael Luiz Klaser <rlklaser@gmail.com>
 *  http://lrm.icmc.usp.br
 *
 *  Apoio FAPESP: 2012/04555-4
 *
 *  This program is free software: you can redistribute it and/or modify
 *  it under the terms of the GNU General Public License as published by
 *  the Free Software Foundation, either version 3 of the License, or
 *  (at your option) any later version.
 *
 *  This program is distributed in the hope that it will be useful,
 *  but WITHOUT ANY WARRANTY; without even the implied warranty of
 *  MERCHANTABILITY or FITNESS FOR A PARTICULAR PURPOSE.  See the
 *  GNU General Public License for more details.
 *
 *  You should have received a copy of the GNU General Public License
 *  along with this program.  If not, see <http://www.gnu.org/licenses/>.
 */

/**
 * @file front.suspension.urdf.xacro
 * @brief 
 * @author Rafael Luiz Klaser <rlklaser@gmail.com>
 * @date Dez 12, 2012
 *
 */
-->
<robot
	xmlns:xi="http://www.w3.org/2001/XInclude"
	xmlns:xacro="http://ros.org/wiki/xacro"
>
	<xacro:macro
		name="front_bar"
		params="side"
	>
		<joint
			name="joint_front_${side}_bar"
			type="revolute"
		>
			<parent link="front_${side}_suspension_link" />
			<child link="front_${side}_bar_link" />
			<origin
				xyz="0.0 0.0 0"
				rpy="0 0 0" />
			<axis
				xyz="0 0 1"
				rpy="0 0 0" />
			<limit
				effort="100"
				velocity="10"
				lower="-0.80"
				upper="0.80" />
		</joint>
	</xacro:macro>
</robot>